Time slot   0
ld_routine
Time slot   1
	Loaded a process at input/proc/p0s, PID: 1 PRIO: 130
Time slot   2
	CPU 3: Dispatched process  1
Time slot   3
	Loaded a process at input/proc/m0s, PID: 2 PRIO: 120
liballoc:178
print_pgtbl:
 PDG=b44fb220b3b08680 P4g=b44fb220b3b09690 PUD=b44fb220b3b0a6a0 PMD=b44fb220b3b0b6b0
Time slot   4
	CPU 2: Dispatched process  2
	CPU 3: Put process  1 to run queue
	CPU 3: Dispatched process  1
liballoc:178
print_pgtbl:
 PDG=b4cfc220b3b08680 P4g=b4cfc220b3b09690 PUD=b4cfc220b3b0a6a0 PMD=b4cfc220b3b0b6b0
liballoc:178
print_pgtbl:
 PDG=b44fb220b3b08680 P4g=b44fb220b3b09690 PUD=b44fb220b3b0a6a0 PMD=b44fb220b3b0b6b0
Time slot   5
libfree:218
print_pgtbl:
 PDG=b44fb230b3b08680 P4g=b44fb230b3b09690 PUD=b44fb230b3b0a6a0 PMD=b44fb230b3b0b6b0
	Loaded a process at input/proc/s1, PID: 3 PRIO: 0
liballoc:178
print_pgtbl:
 PDG=b4cfc220b3b0f070 P4g=b4cfc220b3b10080 PUD=b4cfc220b3b11090 PMD=b4cfc220b3b120a0
Time slot   6
	CPU 3: Put process  1 to run queue
	CPU 3: Dispatched process  3
	CPU 2: Put process  2 to run queue
	CPU 2: Dispatched process  2
libfree:218
print_pgtbl:
 PDG=b4cfc230b3b0f070 P4g=b4cfc230b3b10080 PUD=b4cfc230b3b11090 PMD=b4cfc230b3b120a0
	CPU 1: Dispatched process  1
	Loaded a process at input/proc/p1s, PID: 4 PRIO: 15
liballoc:178
print_pgtbl:
 PDG=b54fd220b3b15a90 P4g=b54fd220b3b16aa0 PUD=b54fd220b3b17ab0 PMD=b54fd220b3b18ac0
Time slot   7
libwrite:502
print_pgtbl:
 PDG=b54fd210b3b15a90 P4g=b54fd210b3b16aa0 PUD=b54fd210b3b17ab0 PMD=b54fd210b3b18ac0
	CPU 0: Dispatched process  4
liballoc:178
print_pgtbl:
 PDG=b4cfc220b3b15a90 P4g=b4cfc220b3b16aa0 PUD=b4cfc220b3b17ab0 PMD=b4cfc220b3b18ac0
Time slot   8
	CPU 3: Put process  3 to run queue
	CPU 3: Dispatched process  3
	CPU 1: Put process  1 to run queue
	CPU 1: Dispatched process  1
	CPU 2: Put process  2 to run queue
	CPU 2: Dispatched process  2
libwrite:502
print_pgtbl:
 PDG=b4cfc210b3b15a90 P4g=b4cfc210b3b16aa0 PUD=b4cfc210b3b17ab0 PMD=b4cfc210b3b18ac0
Time slot   9
libread:426
libwrite:502
print_pgtbl:
 PDG=b4cfc210b3b15a90 P4g=b4cfc210b3b16aa0 PUD=b4cfc210b3b17ab0 PMD=b4cfc210b3b18ac0
	CPU 0: Put process  4 to run queue
	CPU 0: Dispatched process  4
	Loaded a process at input/proc/s3, PID: 5 PRIO: 39
Time slot  10
	CPU 3: Put process  3 to run queue
	CPU 3: Dispatched process  3
	CPU 1: Put process  1 to run queue
	CPU 1: Dispatched process  5
	CPU 2: Processed  2 has finished
	CPU 2: Dispatched process  1
	Loaded a process at input/proc/s2, PID: 6 PRIO: 120
Time slot  11
libfree:218
print_pgtbl:
 PDG=b4cfc230b3b22d00 P4g=b4cfc230b3b23d10 PUD=b4cfc230b3b24d20 PMD=b4cfc230b3b25d30
	CPU 0: Put process  4 to run queue
	CPU 0: Dispatched process  4
	Loaded a process at input/proc/m1s, PID: 7 PRIO: 15
Time slot  12
	CPU 3: Put process  3 to run queue
	CPU 3: Dispatched process  3
	CPU 1: Put process  5 to run queue
	CPU 1: Dispatched process  7
	CPU 2: Put process  1 to run queue
	CPU 2: Dispatched process  5
	Loaded a process at input/proc/s0, PID: 8 PRIO: 38
liballoc:178
print_pgtbl:
 PDG=b54fd220b3b2fe40 P4g=b54fd220b3b30e50 PUD=b54fd220b3b31e60 PMD=b54fd220b3b32e70
Time slot  13
	CPU 0: Put process  4 to run queue
	CPU 0: Dispatched process  4
liballoc:178
print_pgtbl:
 PDG=b54fd220b3b2fe40 P4g=b54fd220b3b30e50 PUD=b54fd220b3b31e60 PMD=b54fd220b3b32e70
Time slot  14
	CPU 3: Put process  3 to run queue
	CPU 3: Dispatched process  3
	CPU 2: Put process  5 to run queue
	CPU 2: Dispatched process  8
	CPU 1: Put process  7 to run queue
	CPU 1: Dispatched process  7
libfree:218
print_pgtbl:
 PDG=b54fd230b3b2fe40 P4g=b54fd230b3b30e50 PUD=b54fd230b3b31e60 PMD=b54fd230b3b32e70
Time slot  15
	CPU 3: Processed  3 has finished
	CPU 3: Dispatched process  5
	CPU 0: Put process  4 to run queue
	CPU 0: Dispatched process  4
liballoc:178
print_pgtbl:
 PDG=b54fd220b3b2fe40 P4g=b54fd220b3b30e50 PUD=b54fd220b3b31e60 PMD=b54fd220b3b32e70
Time slot  16
	CPU 2: Put process  8 to run queue
	CPU 2: Dispatched process  8
	CPU 1: Put process  7 to run queue
	CPU 1: Dispatched process  7
libfree:218
print_pgtbl:
 PDG=b54fd230b3b2fe40 P4g=b54fd230b3b30e50 PUD=b54fd230b3b31e60 PMD=b54fd230b3b32e70
Time slot  17
	CPU 3: Put process  5 to run queue
	CPU 3: Dispatched process  5
libfree:218
print_pgtbl:
 PDG=b54fd230b3b2fe40 P4g=b54fd230b3b30e50 PUD=b54fd230b3b31e60 PMD=b54fd230b3b32e70
	CPU 0: Put process  4 to run queue
	CPU 0: Dispatched process  4
Time slot  18
	CPU 2: Put process  8 to run queue
	CPU 2: Dispatched process  8
	CPU 1: Processed  7 has finished
	CPU 1: Dispatched process  6
Time slot  19
	CPU 3: Put process  5 to run queue
	CPU 3: Dispatched process  5
	CPU 0: Put process  4 to run queue
	CPU 0: Dispatched process  4
Time slot  20
	CPU 2: Put process  8 to run queue
	CPU 2: Dispatched process  8
	CPU 1: Put process  6 to run queue
	CPU 1: Dispatched process  6
Time slot  21
	CPU 3: Put process  5 to run queue
	CPU 3: Dispatched process  5
	CPU 0: Put process  4 to run queue
	CPU 0: Dispatched process  4
Time slot  22
	CPU 2: Put process  8 to run queue
	CPU 2: Dispatched process  8
	CPU 1: Put process  6 to run queue
	CPU 1: Dispatched process  6
Time slot  23
	CPU 3: Put process  5 to run queue
	CPU 3: Dispatched process  5
	CPU 0: Put process  4 to run queue
	CPU 0: Dispatched process  4
Time slot  24
	CPU 2: Put process  8 to run queue
	CPU 2: Dispatched process  8
	CPU 1: Put process  6 to run queue
	CPU 1: Dispatched process  6
Time slot  25
	CPU 3: Put process  5 to run queue
	CPU 3: Dispatched process  5
	CPU 0: Put process  4 to run queue
	CPU 0: Dispatched process  4
Time slot  26
	CPU 2: Put process  8 to run queue
	CPU 2: Dispatched process  8
	CPU 1: Put process  6 to run queue
	CPU 1: Dispatched process  6
	CPU 0: Processed  4 has finished
	CPU 0: Dispatched process  1
libwrite:502
print_pgtbl:
 PDG=b5cfe210b3b2fe40 P4g=b5cfe210b3b30e50 PUD=b5cfe210b3b31e60 PMD=b5cfe210b3b32e70
Time slot  27
	CPU 3: Processed  5 has finished
	CPU 3 stopped
Time slot  28
	CPU 2: Put process  8 to run queue
	CPU 2: Dispatched process  8
	CPU 1: Put process  6 to run queue
	CPU 1: Dispatched process  6
	CPU 0: Put process  1 to run queue
	CPU 0: Dispatched process  1
libread:426
Time slot  29
	CPU 2: Processed  8 has finished
	CPU 2 stopped
libwrite:502
print_pgtbl:
 PDG=b5cfe210b3b2fe40 P4g=b5cfe210b3b30e50 PUD=b5cfe210b3b31e60 PMD=b5cfe210b3b32e70
Time slot  30
	CPU 1: Processed  6 has finished
	CPU 1 stopped
	CPU 0: Put process  1 to run queue
	CPU 0: Dispatched process  1
libread:426
Time slot  31
	CPU 0: Processed  1 has finished
	CPU 0 stopped
